<?xml version="1.0" encoding="utf-8"?>
<robot name="fr5_ag95">
  <link name="base_link">
    <inertial>
      <origin xyz="-0.00031896 -0.00029673 0.042463" rpy="0 0 0" />
      <mass value="1.6185" />
      <inertia ixx="0.0030836" ixy="1.5354E-05" ixz="-1.9315E-05" iyy="0.0030825" iyz="-1.7918E-05" izz="0.0045209" />
    </inertial>
    <visual>
      <origin xyz="0 0 0" rpy="0 0 0" />
      <geometry>
        <mesh filename="package://dcp_description/meshes/robot/fr5/base_link.STL" />
      </geometry>
      <material name="">
        <color rgba="0.89804 0.91765 0.92941 1" />
      </material>
    </visual>
    <collision>
      <origin xyz="0 0 0" rpy="0 0 0" />
      <geometry>
        <mesh filename="package://dcp_description/meshes/robot/fr5/base_link.STL" />
      </geometry>
    </collision>
  </link>
  <joint name="j1" type="revolute">
    <origin xyz="0 0 0" rpy="0 0 0" />
    <parent link="base_link" />
    <child link="shoulder_link" />
    <axis xyz="0 0 1" />
    <limit lower="-3.0543" upper="3.0543" effort="150" velocity="3.15" />
  </joint>
  <link name="shoulder_link">
    <inertial>
      <origin xyz="5.0029E-07 -0.0040922 0.14629" rpy="0 0 0" />
      <mass value="4.3771" />
      <inertia ixx="0.010731" ixy="-8.0587E-09" ixz="-3.6773E-08" iyy="0.010408" iyz="0.00012853" izz="0.0081793" />
    </inertial>
    <visual>
      <origin xyz="0 0 0" rpy="0 0 0" />
      <geometry>
        <mesh filename="package://dcp_description/meshes/robot/fr5/shoulder_link.STL" />
      </geometry>
      <material name="">
        <color rgba="0.89804 0.91765 0.92941 1" />
      </material>
    </visual>
    <collision>
      <origin xyz="0 0 0" rpy="0 0 0" />
      <geometry>
        <mesh filename="package://dcp_description/meshes/robot/fr5/shoulder_link.STL" />
      </geometry>
    </collision>
  </link>
  <joint name="j2" type="revolute">
    <origin xyz="0 0 0.152" rpy="1.5708 0 0" />
    <parent link="shoulder_link" />
    <child link="upperarm_link" />
    <axis xyz="0 0 1" />
    <limit lower="-4.6251" upper="1.4835" effort="150" velocity="3.15" />
  </joint>
  <link name="upperarm_link">
    <inertial>
      <origin xyz="-0.2125 -5.7643E-09 0.1346" rpy="0 0 0" />
      <mass value="14.458" />
      <inertia ixx="0.028392" ixy="-1.337E-07" ixz="-3.9895E-09" iyy="0.4559" iyz="4.214E-08" izz="0.44974" />
    </inertial>
    <visual>
      <origin xyz="0 0 0" rpy="0 0 0" />
      <geometry>
        <mesh filename="package://dcp_description/meshes/robot/fr5/upperarm_link.STL" />
      </geometry>
      <material name="">
        <color rgba="0.89804 0.91765 0.92941 1" />
      </material>
    </visual>
    <collision>
      <origin xyz="0 0 0" rpy="0 0 0" />
      <geometry>
        <mesh filename="package://dcp_description/meshes/robot/fr5/upperarm_link.STL" />
      </geometry>
    </collision>
  </link>
  <joint name="j3" type="revolute">
    <origin xyz="-0.425 0 0" rpy="0 0 0" />
    <parent link="upperarm_link" />
    <child link="forearm_link" />
    <axis xyz="0 0 1" />
    <limit lower="-2.8274" upper="2.8274" effort="150" velocity="3.15" />
  </joint>
  <link name="forearm_link">
    <inertial>
      <origin xyz="-0.18793 -8.4503E-07 0.0066357" rpy="0 0 0" />
      <mass value="7.6737" />
      <inertia ixx="0.0085096" ixy="2.1613E-06" ixz="-0.0068678" iyy="0.16971" iyz="3.7086E-08" izz="0.16854" />
    </inertial>
    <visual>
      <origin xyz="0 0 0" rpy="0 0 0" />
      <geometry>
        <mesh filename="package://dcp_description/meshes/robot/fr5/forearm_link.STL" />
      </geometry>
      <material name="">
        <color rgba="0.89804 0.91765 0.92941 1" />
      </material>
    </visual>
    <collision>
      <origin xyz="0 0 0" rpy="0 0 0" />
      <geometry>
        <mesh filename="package://dcp_description/meshes/robot/fr5/forearm_link.STL" />
      </geometry>
    </collision>
  </link>
  <joint name="j4" type="revolute">
    <origin xyz="-0.39501 0 0" rpy="0 0 0" />
    <parent  link="forearm_link" />
    <child link="wrist1_link" />
    <axis xyz="0 0 1" />
    <limit lower="-4.6251" upper="1.4835" effort="28" velocity="3.2" />
  </joint>
  <link name="wrist1_link">
    <inertial>
      <origin xyz="4.98E-07 -0.003754 0.097155" rpy="0 0 0" />
      <mass value="1.6266" />
      <inertia ixx="0.00216" ixy="4.888E-09" ixz="3.1528E-08" iyy="0.0015455" iyz="3.7678E-05" izz="0.0019902" />
    </inertial>
    <visual>
      <origin xyz="0 0 0" rpy="0 0 0" />
      <geometry>
        <mesh filename="package://dcp_description/meshes/robot/fr5/wrist1_link.STL" />
      </geometry>
      <material name="">
        <color rgba="0.89804 0.91765 0.92941 1" />
      </material>
    </visual>
    <collision>
      <origin xyz="0 0 0" rpy="0 0 0" />
      <geometry>
        <mesh filename="package://dcp_description/meshes/robot/fr5/wrist1_link.STL" />
      </geometry>
    </collision>
  </link>
  <joint name="j5" type="revolute">
    <origin xyz="0 0 0.1021" rpy="1.5708 0 0" />
    <parent link="wrist1_link" />
    <child link="wrist2_link" />
    <axis xyz="0 0 1" />
    <limit lower="-3.0543" upper="3.0543" effort="28" velocity="3.2" />
  </joint>
  <link
    name="wrist2_link">
    <inertial>
      <origin xyz="-4.5588E-07 0.0038617 0.098257" rpy="0 0 0" />
      <mass value="1.5812" />
      <inertia ixx="0.0020612" ixy="8.7064E-09" ixz="-3.4742E-08" iyy="0.0014477" iyz="-2.8534E-05" izz="0.0019573" />
    </inertial>
    <visual>
      <origin xyz="0 0 0" rpy="0 0 0" />
      <geometry>
        <mesh filename="package://dcp_description/meshes/robot/fr5/wrist2_link.STL" />
      </geometry>
      <material name="">
        <color rgba="0.89804 0.91765 0.92941 1" />
      </material>
    </visual>
    <collision>
      <origins xyz="0 0 0" rpy="0 0 0" />
      <geometry>
        <mesh filename="package://dcp_description/meshes/robot/fr5/wrist2_link.STL" />
      </geometry>
    </collision>
  </link>
  <joint name="j6" type="revolute">
    <origin xyz="0 0 0.102" rpy="-1.5708 0 0" />
    <parent link="wrist2_link" />
    <child link="wrist3_link" />
    <axis xyz="0 0 1" />
    <limit lower="-3.0543" upper="3.0543" effort="28" velocity="3.2" />
  </joint>
  <link name="wrist3_link">
    <inertial>
      <origin xyz="7.7496E-05 1.7751E-05 0.076122" rpy="0 0 0" />
      <mass value="0.52542" />
      <inertia ixx="0.00027721" ixy="-1.8677E-09" ixz="-1.188E-07" iyy="0.00027839" iyz="2.2607E-07" izz="0.00041605" />
    </inertial>
    <visual>
      <origin xyz="0 0 0" rpy="0 0 0" />
      <geometry>
        <mesh filename="package://dcp_description/meshes/robot/fr5/wrist3_link.STL" />
      </geometry>
      <material name="">
        <color rgba="0.89804 0.91765 0.92941 1" />
      </material>
    </visual>
    <collision>
      <origin xyz="0 0 0" rpy="0 0 0" />
      <geometry>
        <mesh filename="package://dcp_description/meshes/robot/fr5/wrist3_link.STL" />
      </geometry>
    </collision>
  </link>
  <joint name="wrist3-flange" type="fixed">
    <parent link="wrist3_link"/>
    <child link="flange"/>
    <origin rpy="0 -1.5707963267948966 -1.5707963267948966" xyz="0 0 0.1"/>
  </joint>
  <link name="flange"/>
  <joint name="flange-tool0" type="fixed">
    <origin rpy="1.5707963267948966 0 1.5707963267948966" xyz="0 0 0"/>
    <parent link="flange"/>
    <child link="tool0"/>
  </joint>
  <link name="tool0"/>

  <!-- Gripper -->
  <joint name="gripper_base_joint" type="fixed">
    <parent link="tool0"/>
    <child link="gripper_base_link"/>
    <origin rpy="0 0 0" xyz="0 0 0"/>
  </joint>
  <link name="gripper_base_link">
    <visual>
      <geometry>
        <mesh filename="package://dcp_description/meshes/gripper/ag95/base_link.STL"/>
      </geometry>
    </visual>
    <collision>
      <geometry>
        <mesh filename="package://dcp_description/meshes/gripper/ag95/base_link.STL"/>
      </geometry>
    </collision>
    <inertial>
      <mass value="0.83416" />
      <origin xyz="0.0 0.0 0.0" />
      <inertia ixx = "0.0013016" ixy = "-6.9374e-07" ixz = "5.9848e-07"
               iyx = "0.000000" iyy = "0.00049972" iyz = "2.0244E-07"
               izx = "0.000000" izy = "0.000000" izz = "0.001498" />
    </inertial>
  </link>
  <joint name="gripper_finger1_joint" type="revolute">
    <parent link="gripper_base_link"/>
    <child link="gripper_finger1_knuckle_link"/>
    <axis xyz="0 -1 0"/>
    <origin rpy="0.0 0.0 3.14" xyz="-0.016 0 0.10586"/>
    <limit lower="0.0" upper="0.6524" velocity="2.0" effort="1000"/>
  </joint>
  <joint name="gripper_finger2_joint" type="revolute">
    <parent link="gripper_base_link"/>
    <child link="gripper_finger2_knuckle_link"/>
    <axis xyz="0 -1 0"/>
    <origin rpy="0.0 0.0 0.0" xyz="0.016  0 0.10586 "/>
    <limit lower="-3.14" upper="3.14" velocity="100.0" effort="1000"/>
    <mimic joint="gripper_finger1_joint"/>
  </joint>
  <link name="gripper_finger1_knuckle_link">
    <visual>
      <geometry>
          <mesh filename="package://dcp_description/meshes/gripper/ag95/crank_Link.STL"/>
      </geometry>
    </visual>
    <collision>
      <geometry>
          <mesh filename="package://dcp_description/meshes/gripper/ag95/crank_Link.STL"/>
      </geometry>
    </collision>
    <inertial>
      <mass value="0.011111" />
      <origin xyz="0.0 0.0 0.0" />
      <inertia ixx = "3.88172e-06" ixy = "-2.29456e-13" ixz = "8.33e-07"
               iyx = "0.000000" iyy = "1.92174e-06" iyz = "2.04435e-13"
               izx = "0.000000" izy = "0.000000" izz = "4.32374e-06" />
    </inertial>
  </link>
  <link name="gripper_finger2_knuckle_link">
    <visual>
      <geometry>
          <mesh filename="package://dcp_description/meshes/gripper/ag95/crank_Link.STL"/>
      </geometry>
    </visual>
    <collision>
      <geometry>
          <mesh filename="package://dcp_description/meshes/gripper/ag95/crank_Link.STL"/>
      </geometry>
    </collision>
    <inertial>
      <mass value="0.011111" />
      <origin xyz="0.0 0.0 0.0" />
      <inertia ixx = "3.88172e-06" ixy = "-2.29456e-13" ixz = "8.33e-07"
               iyx = "0.000000" iyy = "1.92174e-06" iyz = "2.04435e-13"
               izx = "0.000000" izy = "0.000000" izz = "4.32374e-06" />
    </inertial>
  </link>
  <joint name="gripper_finger1_finger_joint" type="continuous">
    <parent link="gripper_finger1_knuckle_link"/>
    <child link="gripper_finger1_finger_link"/>
    <axis xyz="0 -1 0"/>
    <origin xyz="0.0292080077784 0.0 -0.0227132622407" rpy="0 0 0" />
    <limit lower="-3.14" upper="3.14" velocity="100.0" effort="0.1"/>
    <mimic joint="gripper_finger1_joint" multiplier="0.4563942" offset="0"/>
  </joint>
  <joint name="gripper_finger2_finger_joint" type="continuous">
    <parent link="gripper_finger2_knuckle_link"/>
    <child link="gripper_finger2_finger_link"/>
    <axis xyz="0 -1 0"/>
    <origin xyz="0.0292080077784 0.0 -0.0227132622407" rpy="0 0 0" />
    <limit lower="-3.14" upper="3.14" velocity="100.0" effort="0.1"/>
    <mimic joint="gripper_finger1_joint" multiplier="0.4563942" offset="0"/>
  </joint>
  <link name="gripper_finger1_finger_link">
    <visual>
      <geometry>
          <mesh filename="package://dcp_description/meshes/gripper/ag95/rod_Link.STL"/>
      </geometry>
    </visual>
    <collision>
      <geometry>
          <mesh filename="package://dcp_description/meshes/gripper/ag95/rod_Link.STL"/>
      </geometry>
    </collision>
    <inertial>
      <mass value="0.0222871" />
      <origin xyz="0.0 0.0 0.0" />
      <inertia ixx = "8.72836e-06" ixy = "7.0843e-15" ixz = "-2.18833e-06"
               iyx = "-0.000002" iyy = "7.26157e-06" iyz = "7.6579e-15"
               izx = "0.000000" izy = "0.000000" izz = "3.3425e-06" />
    </inertial>
  </link>
  <link name="gripper_finger2_finger_link">
    <visual>
        <geometry>
            <mesh filename="package://dcp_description/meshes/gripper/ag95/rod_Link.STL"/>
        </geometry>
    </visual>
    <collision>
      <geometry>
          <mesh filename="package://dcp_description/meshes/gripper/ag95/rod_Link.STL"/>
      </geometry>
    </collision>
    <inertial>
      <mass value="0.0222871" />
      <origin xyz="0.0 0.0 0.0" />
      <inertia ixx = "8.72836e-06" ixy = "7.0843e-15" ixz = "-2.18833e-06"
               iyx = "-0.000002" iyy = "7.26157e-06" iyz = "7.6579e-15"
               izx = "0.000000" izy = "0.000000" izz = "3.3425e-06" />
    </inertial>
  </link>
  <joint name="gripper_finger1_inner_knuckle_joint" type="continuous">
    <parent link="gripper_base_link"/>
    <child link="gripper_finger1_inner_knuckle_link"/>
    <axis xyz="0 -1 0"/>
    <origin rpy="0.0 0.0 3.14" xyz="-0.016 0 0.10586"/>
    <limit lower="-3.14" upper="3.14" velocity="100.0" effort="0.1"/>
    <mimic joint="gripper_finger1_joint" multiplier="1.49462955"  offset="0"/>
  </joint>
  <joint name="gripper_finger2_inner_knuckle_joint" type="continuous">
    <parent link="gripper_base_link"/>
    <child link="gripper_finger2_inner_knuckle_link"/>
    <axis xyz="0 -1 0"/>
    <origin rpy="0.0 0.0 0.0" xyz="0.016 0 0.10586"/>
    <limit lower="-3.14" upper="3.14" velocity="100.0" effort="0.1"/>
    <mimic joint="gripper_finger1_joint" multiplier="1.49462955"  offset="0"/>
  </joint>
  <link name="gripper_finger1_inner_knuckle_link">
    <visual>
      <geometry>
          <mesh filename="package://dcp_description/meshes/gripper/ag95/proximal_phalanx_Link.STL"/>
      </geometry>
    </visual>
    <collision>
      <geometry>
          <mesh filename="package://dcp_description/meshes/gripper/ag95/proximal_phalanx_Link.STL"/>
      </geometry>
    </collision>
    <inertial>
      <mass value="0.0318004" />
      <origin xyz="0.0 0.0 0.0" />
      <inertia ixx = "1.39848e-05" ixy = "-9.54763e-15" ixz = "-5.01422e-06"
               iyx = "0.000000" iyy = "1.04943e-05" iyz = "8.94585e-16"
               izx = "0.000000" izy = "0.000000" izz = "1.36183e-05" />
    </inertial>
  </link>
  <link name="gripper_finger2_inner_knuckle_link">
    <visual>
      <geometry>
          <mesh filename="package://dcp_description/meshes/gripper/ag95/proximal_phalanx_Link.STL"/>
      </geometry>
    </visual>
    <collision>
      <geometry>
          <mesh filename="package://dcp_description/meshes/gripper/ag95/proximal_phalanx_Link.STL"/>
      </geometry>
    </collision>
    <inertial>
      <mass value="0.0318004" />
      <origin xyz="0.0 0.0 0.0" />
      <inertia ixx = "1.39848e-05" ixy = "-9.54763e-15" ixz = "-5.01422e-06"
               iyx = "0.000000" iyy = "1.04943e-05" iyz = "8.94585e-16"
               izx = "0.000000" izy = "0.000000" izz = "1.36183e-05" />
    </inertial>
  </link>
  <joint name="gripper_finger1_finger_tip_joint" type="continuous">
    <parent link="gripper_finger1_inner_knuckle_link"/>
    <child link="gripper_finger1_finger_tip_link"/>
      <axis xyz="0 1 0"/>
      <origin xyz="0.0394969463769 0.0 0.0382752038125 " rpy="0.0 0.0 0.0"/>
      <limit lower="-3.14" upper="3.14" velocity="100.0" effort="0.1"/>
      <mimic joint="gripper_finger1_joint" multiplier="1.49462955"/>
  </joint>
  <joint name="gripper_finger2_finger_tip_joint" type="continuous">
    <parent link="gripper_finger2_inner_knuckle_link"/>
    <child link="gripper_finger2_finger_tip_link"/>
    <axis xyz="0 1 0"/>
    <origin rpy="0.0 0.0 0.0" xyz="0.0394969463769  0.0 0.0382752038125  "/>
    <limit lower="-3.14" upper="3.14" velocity="100.0" effort="0.1"/>
    <mimic joint="gripper_finger1_joint" multiplier="1.49462955"/>
  </joint>
  <link name="gripper_finger1_finger_tip_link">
    <visual>
      <geometry>
          <mesh filename="package://dcp_description/meshes/gripper/ag95/distal_phalanx_Link.STL"/>
      </geometry>
    </visual>
    <collision>
      <geometry>
          <mesh filename="package://dcp_description/meshes/gripper/ag95/distal_phalanx_Link.STL"/>
      </geometry>
    </collision>
    <inertial>
      <mass value="0.0124305" />
      <origin xyz="0.0 0.0 0.0" />
      <inertia ixx = "2.84217e-06" ixy = "-2.48048e-15" ixz = "8.24539e-07"
               iyx = "0.000000" iyy = "3.03961e-06" iyz = "2.16427e-13"
               izx = "0.000000" izy = "0.000000" izz = "1.11815e-06" />
    </inertial>
  </link> 
  <link name="gripper_finger2_finger_tip_link">
    <visual>
      <geometry>
          <mesh filename="package://dcp_description/meshes/gripper/ag95/distal_phalanx_Link.STL"/>
      </geometry>
    </visual>
    <collision>
      <geometry>
          <mesh filename="package://dcp_description/meshes/gripper/ag95/distal_phalanx_Link.STL"/>
      </geometry>
    </collision>
    <inertial>
      <mass value="0.0124305" />
      <origin xyz="0.0 0.0 0.0" />
      <inertia ixx = "2.84217e-06" ixy = "-2.48048e-15" ixz = "8.24539e-07"
               iyx = "0.000000" iyy = "3.03961e-06" iyz = "2.16427e-13"
               izx = "0.000000" izy = "0.000000" izz = "1.11815e-06" />
    </inertial>
  </link>
  <joint name="grasp_joint" type="fixed">
    <origin rpy="0 0 0.0" xyz="0 0 0.17"/>
    <axis xyz="0 0 1"/>
    <parent link="gripper_base_link"/>
    <child link="grasp_frame"/>
  </joint>
  <link name="grasp_frame">
    <inertial>
      <!-- Dummy inertial parameters to avoid link lumping-->
      <mass value="0.01"/>
      <inertia ixx="0.0001" ixy="0.0" ixz="0.0" iyy="0.0001" iyz="0.0" izz="0.0001"/>
      <origin rpy="0 0 0" xyz="0 0 0"/>
    </inertial>
  </link>
  
</robot>