<?xml version="1.0" encoding="utf-8"?>
<robot name="fr5_dh3">
  <link name="base_link">
    <inertial>
      <origin xyz="-0.00031896 -0.00029673 0.042463" rpy="0 0 0" />
      <mass value="1.6185" />
      <inertia ixx="0.0030836" ixy="1.5354E-05" ixz="-1.9315E-05" iyy="0.0030825" iyz="-1.7918E-05" izz="0.0045209" />
    </inertial>
    <visual>
      <origin xyz="0 0 0" rpy="0 0 0" />
      <geometry>
        <mesh filename="package://dcp_description/meshes/robot/fr5/base_link.STL" />
      </geometry>
      <material name="">
        <color rgba="0.89804 0.91765 0.92941 1" />
      </material>
    </visual>
    <collision>
      <origin xyz="0 0 0" rpy="0 0 0" />
      <geometry>
        <mesh filename="package://dcp_description/meshes/robot/fr5/base_link.STL" />
      </geometry>
    </collision>
  </link>
  <joint name="j1" type="revolute">
    <origin xyz="0 0 0" rpy="0 0 0" />
    <parent link="base_link" />
    <child link="shoulder_link" />
    <axis xyz="0 0 1" />
    <limit lower="-3.0543" upper="3.0543" effort="150" velocity="3.15" />
  </joint>
  <link name="shoulder_link">
    <inertial>
      <origin xyz="5.0029E-07 -0.0040922 0.14629" rpy="0 0 0" />
      <mass value="4.3771" />
      <inertia ixx="0.010731" ixy="-8.0587E-09" ixz="-3.6773E-08" iyy="0.010408" iyz="0.00012853" izz="0.0081793" />
    </inertial>
    <visual>
      <origin xyz="0 0 0" rpy="0 0 0" />
      <geometry>
        <mesh filename="package://dcp_description/meshes/robot/fr5/shoulder_link.STL" />
      </geometry>
      <material name="">
        <color rgba="0.89804 0.91765 0.92941 1" />
      </material>
    </visual>
    <collision>
      <origin xyz="0 0 0" rpy="0 0 0" />
      <geometry>
        <mesh filename="package://dcp_description/meshes/robot/fr5/shoulder_link.STL" />
      </geometry>
    </collision>
  </link>
  <joint name="j2" type="revolute">
    <origin xyz="0 0 0.152" rpy="1.5708 0 0" />
    <parent link="shoulder_link" />
    <child link="upperarm_link" />
    <axis xyz="0 0 1" />
    <limit lower="-4.6251" upper="1.4835" effort="150" velocity="3.15" />
  </joint>
  <link name="upperarm_link">
    <inertial>
      <origin xyz="-0.2125 -5.7643E-09 0.1346" rpy="0 0 0" />
      <mass value="14.458" />
      <inertia ixx="0.028392" ixy="-1.337E-07" ixz="-3.9895E-09" iyy="0.4559" iyz="4.214E-08" izz="0.44974" />
    </inertial>
    <visual>
      <origin xyz="0 0 0" rpy="0 0 0" />
      <geometry>
        <mesh filename="package://dcp_description/meshes/robot/fr5/upperarm_link.STL" />
      </geometry>
      <material name="">
        <color rgba="0.89804 0.91765 0.92941 1" />
      </material>
    </visual>
    <collision>
      <origin xyz="0 0 0" rpy="0 0 0" />
      <geometry>
        <mesh filename="package://dcp_description/meshes/robot/fr5/upperarm_link.STL" />
      </geometry>
    </collision>
  </link>
  <joint name="j3" type="revolute">
    <origin xyz="-0.425 0 0" rpy="0 0 0" />
    <parent link="upperarm_link" />
    <child link="forearm_link" />
    <axis xyz="0 0 1" />
    <limit lower="-2.8274" upper="2.8274" effort="150" velocity="3.15" />
  </joint>
  <link name="forearm_link">
    <inertial>
      <origin xyz="-0.18793 -8.4503E-07 0.0066357" rpy="0 0 0" />
      <mass value="7.6737" />
      <inertia ixx="0.0085096" ixy="2.1613E-06" ixz="-0.0068678" iyy="0.16971" iyz="3.7086E-08" izz="0.16854" />
    </inertial>
    <visual>
      <origin xyz="0 0 0" rpy="0 0 0" />
      <geometry>
        <mesh filename="package://dcp_description/meshes/robot/fr5/forearm_link.STL" />
      </geometry>
      <material name="">
        <color rgba="0.89804 0.91765 0.92941 1" />
      </material>
    </visual>
    <collision>
      <origin xyz="0 0 0" rpy="0 0 0" />
      <geometry>
        <mesh filename="package://dcp_description/meshes/robot/fr5/forearm_link.STL" />
      </geometry>
    </collision>
  </link>
  <joint name="j4" type="revolute">
    <origin xyz="-0.39501 0 0" rpy="0 0 0" />
    <parent  link="forearm_link" />
    <child link="wrist1_link" />
    <axis xyz="0 0 1" />
    <limit lower="-4.6251" upper="1.4835" effort="28" velocity="3.2" />
  </joint>
  <link name="wrist1_link">
    <inertial>
      <origin xyz="4.98E-07 -0.003754 0.097155" rpy="0 0 0" />
      <mass value="1.6266" />
      <inertia ixx="0.00216" ixy="4.888E-09" ixz="3.1528E-08" iyy="0.0015455" iyz="3.7678E-05" izz="0.0019902" />
    </inertial>
    <visual>
      <origin xyz="0 0 0" rpy="0 0 0" />
      <geometry>
        <mesh filename="package://dcp_description/meshes/robot/fr5/wrist1_link.STL" />
      </geometry>
      <material name="">
        <color rgba="0.89804 0.91765 0.92941 1" />
      </material>
    </visual>
    <collision>
      <origin xyz="0 0 0" rpy="0 0 0" />
      <geometry>
        <mesh filename="package://dcp_description/meshes/robot/fr5/wrist1_link.STL" />
      </geometry>
    </collision>
  </link>
  <joint name="j5" type="revolute">
    <origin xyz="0 0 0.1021" rpy="1.5708 0 0" />
    <parent link="wrist1_link" />
    <child link="wrist2_link" />
    <axis xyz="0 0 1" />
    <limit lower="-3.0543" upper="3.0543" effort="28" velocity="3.2" />
  </joint>
  <link
    name="wrist2_link">
    <inertial>
      <origin xyz="-4.5588E-07 0.0038617 0.098257" rpy="0 0 0" />
      <mass value="1.5812" />
      <inertia ixx="0.0020612" ixy="8.7064E-09" ixz="-3.4742E-08" iyy="0.0014477" iyz="-2.8534E-05" izz="0.0019573" />
    </inertial>
    <visual>
      <origin xyz="0 0 0" rpy="0 0 0" />
      <geometry>
        <mesh filename="package://dcp_description/meshes/robot/fr5/wrist2_link.STL" />
      </geometry>
      <material name="">
        <color rgba="0.89804 0.91765 0.92941 1" />
      </material>
    </visual>
    <collision>
      <origins xyz="0 0 0" rpy="0 0 0" />
      <geometry>
        <mesh filename="package://dcp_description/meshes/robot/fr5/wrist2_link.STL" />
      </geometry>
    </collision>
  </link>
  <joint name="j6" type="revolute">
    <origin xyz="0 0 0.102" rpy="-1.5708 0 0" />
    <parent link="wrist2_link" />
    <child link="wrist3_link" />
    <axis xyz="0 0 1" />
    <limit lower="-3.0543" upper="3.0543" effort="28" velocity="3.2" />
  </joint>
  <link name="wrist3_link">
    <inertial>
      <origin xyz="7.7496E-05 1.7751E-05 0.076122" rpy="0 0 0" />
      <mass value="0.52542" />
      <inertia ixx="0.00027721" ixy="-1.8677E-09" ixz="-1.188E-07" iyy="0.00027839" iyz="2.2607E-07" izz="0.00041605" />
    </inertial>
    <visual>
      <origin xyz="0 0 0" rpy="0 0 0" />
      <geometry>
        <mesh filename="package://dcp_description/meshes/robot/fr5/wrist3_link.STL" />
      </geometry>
      <material name="">
        <color rgba="0.89804 0.91765 0.92941 1" />
      </material>
    </visual>
    <collision>
      <origin xyz="0 0 0" rpy="0 0 0" />
      <geometry>
        <mesh filename="package://dcp_description/meshes/robot/fr5/wrist3_link.STL" />
      </geometry>
    </collision>
  </link>
  <joint name="wrist3-flange" type="fixed">
    <parent link="wrist3_link"/>
    <child link="flange"/>
    <origin rpy="0 -1.5707963267948966 -1.5707963267948966" xyz="0 0 0.1"/>
  </joint>
  <link name="flange"/>
  <joint name="flange-tool0" type="fixed">
    <origin rpy="1.5707963267948966 0 1.5707963267948966" xyz="0 0 0"/>
    <parent link="flange"/>
    <child link="tool0"/>
  </joint>
  <link name="tool0"/>

  <!-- Gripper -->
  <joint name="gripper_base_joint" type="fixed">
    <parent link="tool0"/>
    <child link="gripper_base_link"/>
    <origin rpy="0 0 0" xyz="0 0 0"/>
  </joint>
  <link
    name="gripper_base_link">
    <inertial>
      <origin
        xyz="-0.000222201146896917 2.99284922239407E-06 0.0365598116000577"
        rpy="0 0 0" />
      <mass
        value="0.359681668644718" />
      <inertia
        ixx="0.000426094138511423"
        ixy="-3.47685971240899E-10"
        ixz="-3.70902449457946E-07"
        iyy="0.000421830861136388"
        iyz="-1.73791620761484E-10"
        izz="0.000552700185384758" />
    </inertial>
    <visual>
      <origin
        xyz="0 0 0"
        rpy="0 0 0" />
      <geometry>
        <mesh
          filename="package://dcp_description/meshes/gripper/dh3/gripper_base_link.STL" />
      </geometry>
      <material
        name="">
        <color
          rgba="1 1 1 1" />
      </material>
    </visual>
    <collision>
      <origin
        xyz="0 0 0"
        rpy="0 0 0" />
      <geometry>
        <mesh
          filename="package://dcp_description/meshes/gripper/dh3/gripper_base_link.STL" />
      </geometry>
    </collision>
  </link>
  <link
    name="finger1_base_link">
    <inertial>
      <origin
        xyz="-0.000601794667080963 -0.00110288755052515 0.00521005597269414"
        rpy="0 0 0" />
      <mass
        value="0.00832299911583519" />
      <inertia
        ixx="9.16214830766921E-07"
        ixy="2.57171997873981E-08"
        ixz="1.43130193804266E-08"
        iyy="1.14280462688504E-06"
        iyz="5.78075867067328E-08"
        izz="1.77055158585085E-06" />
    </inertial>
    <visual>
      <origin
        xyz="0 0 0"
        rpy="0 0 0" />
      <geometry>
        <mesh
          filename="package://dcp_description/meshes/gripper/dh3/finger1_base_link.STL" />
      </geometry>
      <material
        name="">
        <color
          rgba="1 1 1 1" />
      </material>
    </visual>
    <collision>
      <origin
        xyz="0 0 0"
        rpy="0 0 0" />
      <geometry>
        <mesh
          filename="package://dcp_description/meshes/gripper/dh3/finger1_base_link.STL" />
      </geometry>
    </collision>
  </link>
  <joint
    name="finger1_base_joint"
    type="revolute">
    <origin
      xyz="-0.0161724988655456 0.0279961367597022 0.105"
      rpy="0 0 0.523598783277495" />
    <parent
      link="gripper_base_link" />
    <child
      link="finger1_base_link" />
    <axis
      xyz="0 0 -1" />
    <limit
      lower="-1"
      upper="0.54"
      effort="100"
      velocity="100" />
  </joint>
  <link
    name="finger1_link">
    <inertial>
      <origin
        xyz="0.0210050434938139 0.012249999999974 0.0178290357798672"
        rpy="0 0 0" />
      <mass
        value="0.00557906977988049" />
      <inertia
        ixx="8.99405333082292E-07"
        ixy="9.82637628153793E-19"
        ixz="-5.95537945974777E-07"
        iyy="1.3061675562027E-06"
        iyz="6.37604051045675E-19"
        izz="1.24905466077277E-06" />
    </inertial>
    <visual>
      <origin
        xyz="0 0 0"
        rpy="0 0 0" />
      <geometry>
        <mesh
          filename="package://dcp_description/meshes/gripper/dh3/finger1_link.STL" />
      </geometry>
      <material
        name="">
        <color
          rgba="0.0549019607843137 0.0549019607843137 0.0549019607843137 1" />
      </material>
    </visual>
    <collision>
      <origin
        xyz="0 0 0"
        rpy="0 0 0" />
      <geometry>
        <mesh
          filename="package://dcp_description/meshes/gripper/dh3/finger1_link.STL" />
      </geometry>
    </collision>
  </link>
  <joint
    name="finger1_joint"
    type="revolute">
    <origin
      xyz="0.01225 -0.0081568 0.0175"
      rpy="0 0 1.5708" />
    <parent
      link="finger1_base_link" />
    <child
      link="finger1_link" />
    <axis
      xyz="0 -1 0" />
    <limit
      lower="0"
      upper="1.16"
      effort="100"
      velocity="100" />
  </joint>
  <link
    name="finger1_tip_link">
    <inertial>
      <origin
        xyz="0.000977109926666546 0.0123819370127123 0.0136590907193947"
        rpy="0 0 0" />
      <mass
        value="0.0107564294883422" />
      <inertia
        ixx="1.48949781713587E-06"
        ixy="-7.10872889918193E-09"
        ixz="1.38025837549055E-07"
        iyy="1.35009809053808E-06"
        iyz="1.24264254163864E-08"
        izz="4.77788297009959E-07" />
    </inertial>
    <visual>
      <origin
        xyz="0 0 0"
        rpy="0 0 0" />
      <geometry>
        <mesh
          filename="package://dcp_description/meshes/gripper/dh3/finger1_tip_link.STL" />
      </geometry>
      <material
        name="">
        <color
          rgba="1 1 1 1" />
      </material>
    </visual>
    <collision>
      <origin
        xyz="0 0 0"
        rpy="0 0 0" />
      <geometry>
        <mesh
          filename="package://dcp_description/meshes/gripper/dh3/finger1_tip_link.STL" />
      </geometry>
    </collision>
  </link>
  <joint
    name="finger1_tip_joint"
    type="revolute">
    <origin
      xyz="0.044029 0 0.032962"
      rpy="0 0 0" />
    <parent
      link="finger1_link" />
    <child
      link="finger1_tip_link" />
    <axis
      xyz="0 -1 0" />
    <limit
      lower="-3.14"
      upper="3.14"
      effort="100"
      velocity="100" />
    <mimic
      joint="finger1_joint"
      multiplier="-1"
      offset="0" />
  </joint>
  <link
    name="finger1_outlet_link">
    <inertial>
      <origin
        xyz="0.0205745260056277 -0.00269403354044023 0.0154029170399833"
        rpy="0 0 0" />
      <mass
        value="0.00494212097275844" />
      <inertia
        ixx="3.17521820164163E-07"
        ixy="-1.11658813824013E-10"
        ixz="-3.22040978315679E-07"
        iyy="7.52126023069253E-07"
        iyz="-8.36396169396533E-11"
        izz="5.06597025546867E-07" />
    </inertial>
    <visual>
      <origin
        xyz="0 0 0"
        rpy="0 0 0" />
      <geometry>
        <mesh
          filename="package://dcp_description/meshes/gripper/dh3/finger1_outlet_link.STL" />
      </geometry>
      <material
        name="">
        <color
          rgba="1 1 1 1" />
      </material>
    </visual>
    <collision>
      <origin
        xyz="0 0 0"
        rpy="0 0 0" />
      <geometry>
        <mesh
          filename="package://dcp_description/meshes/gripper/dh3/finger1_outlet_link.STL" />
      </geometry>
    </collision>
  </link>
  <joint
    name="finger1_outlet_joint"
    type="revolute">
    <origin
      xyz="-0.01035 0.0081568 0.0098929"
      rpy="0 0 1.5708" />
    <parent
      link="finger1_base_link" />
    <child
      link="finger1_outlet_link" />
    <axis
      xyz="0 1 0" />
    <limit
      lower="-3.14"
      upper="3.14"
      effort="100"
      velocity="100" />
    <mimic
      joint="finger1_joint"
      multiplier="-1"
      offset="0" />
  </joint>
  <link
    name="finger2_base_link">
    <inertial>
      <origin
        xyz="-0.000601794667086514 -0.00110288755052199 0.00521005597269419"
        rpy="0 0 0" />
      <mass
        value="0.00832299911583519" />
      <inertia
        ixx="9.16214830767147E-07"
        ixy="2.57171997885585E-08"
        ixz="1.43130193807236E-08"
        iyy="1.14280462688473E-06"
        iyz="5.78075867066608E-08"
        izz="1.77055158585084E-06" />
    </inertial>
    <visual>
      <origin
        xyz="0 0 0"
        rpy="0 0 0" />
      <geometry>
        <mesh
          filename="package://dcp_description/meshes/gripper/dh3/finger2_base_link.STL" />
      </geometry>
      <material
        name="">
        <color
          rgba="1 1 1 1" />
      </material>
    </visual>
    <collision>
      <origin
        xyz="0 0 0"
        rpy="0 0 0" />
      <geometry>
        <mesh
          filename="package://dcp_description/meshes/gripper/dh3/finger2_base_link.STL" />
      </geometry>
    </collision>
  </link>
  <joint
    name="finger2_base_joint"
    type="fixed">
    <origin
      xyz="0.032325 0 0.105"
      rpy="0 0 -1.5708" />
    <parent
      link="gripper_base_link" />
    <child
      link="finger2_base_link" />
    <axis
      xyz="0 0 0" />
  </joint>
  <link
    name="finger2_link">
    <inertial>
      <origin
        xyz="0.021005043493832 0.0122499999999494 0.0178290357798643"
        rpy="0 0 0" />
      <mass
        value="0.00557906977988033" />
      <inertia
        ixx="8.99405333082248E-07"
        ixy="1.40895930945985E-18"
        ixz="-5.95537945974751E-07"
        iyy="1.30616755620265E-06"
        iyz="1.47278790722963E-18"
        izz="1.24905466077276E-06" />
    </inertial>
    <visual>
      <origin
        xyz="0 0 0"
        rpy="0 0 0" />
      <geometry>
        <mesh
          filename="package://dcp_description/meshes/gripper/dh3/finger2_link.STL" />
      </geometry>
      <material
        name="">
        <color
          rgba="0.0549019607843137 0.0549019607843137 0.0549019607843137 1" />
      </material>
    </visual>
    <collision>
      <origin
        xyz="0 0 0"
        rpy="0 0 0" />
      <geometry>
        <mesh
          filename="package://dcp_description/meshes/gripper/dh3/finger2_link.STL" />
      </geometry>
    </collision>
  </link>
  <joint
    name="finger2_joint"
    type="revolute">
    <origin
      xyz="0.01225 -0.0081568 0.0175"
      rpy="0 0 1.5708" />
    <parent
      link="finger2_base_link" />
    <child
      link="finger2_link" />
    <axis
      xyz="0 -1 0" />
    <limit
      lower="-3.14"
      upper="3.14"
      effort="100"
      velocity="100" />
    <mimic
      joint="finger1_joint"
      multiplier="1"
      offset="0" />
  </joint>
  <link
    name="finger2_tip_link">
    <inertial>
      <origin
        xyz="0.000977109970519835 0.0123819365363909 0.0136590906877767"
        rpy="0 0 0" />
      <mass
        value="0.0107564295938579" />
      <inertia
        ixx="1.48949781977635E-06"
        ixy="-7.10872109767472E-09"
        ixz="1.38025837268698E-07"
        iyy="1.35009809568266E-06"
        iyz="1.24264681742315E-08"
        izz="4.77788294510709E-07" />
    </inertial>
    <visual>
      <origin
        xyz="0 0 0"
        rpy="0 0 0" />
      <geometry>
        <mesh
          filename="package://dcp_description/meshes/gripper/dh3/finger2_tip_link.STL" />
      </geometry>
      <material
        name="">
        <color
          rgba="1 1 1 1" />
      </material>
    </visual>
    <collision>
      <origin
        xyz="0 0 0"
        rpy="0 0 0" />
      <geometry>
        <mesh
          filename="package://dcp_description/meshes/gripper/dh3/finger2_tip_link.STL" />
      </geometry>
    </collision>
  </link>
  <joint
    name="finger2_tip_joint"
    type="revolute">
    <origin
      xyz="0.044029 0 0.032962"
      rpy="0 0 0" />
    <parent
      link="finger2_link" />
    <child
      link="finger2_tip_link" />
    <axis
      xyz="0 -1 0" />
    <limit
      lower="-3.14"
      upper="3.14"
      effort="100"
      velocity="100" />
    <mimic
      joint="finger1_joint"
      multiplier="-1"
      offset="0" />
  </joint>
  <link
    name="finger2_outlet_link">
    <inertial>
      <origin
        xyz="0.0205745216753029 -0.00269403287328564 0.0154029129942138"
        rpy="0 0 0" />
      <mass
        value="0.00494212190694487" />
      <inertia
        ixx="3.17522151991331E-07"
        ixy="-1.11440245000629E-10"
        ixz="-3.22041349248125E-07"
        iyy="7.52126778397778E-07"
        iyz="-8.34843588255468E-11"
        izz="5.06597462640552E-07" />
    </inertial>
    <visual>
      <origin
        xyz="0 0 0"
        rpy="0 0 0" />
      <geometry>
        <mesh
          filename="package://dcp_description/meshes/gripper/dh3/finger2_outlet_link.STL" />
      </geometry>
      <material
        name="">
        <color
          rgba="1 1 1 1" />
      </material>
    </visual>
    <collision>
      <origin
        xyz="0 0 0"
        rpy="0 0 0" />
      <geometry>
        <mesh
          filename="package://dcp_description/meshes/gripper/dh3/finger2_outlet_link.STL" />
      </geometry>
    </collision>
  </link>
  <joint
    name="finger2_outlet_joint"
    type="revolute">
    <origin
      xyz="-0.01035 0.0081568 0.0098929"
      rpy="0 0 1.5708" />
    <parent
      link="finger2_base_link" />
    <child
      link="finger2_outlet_link" />
    <axis
      xyz="0 1 0" />
    <limit
      lower="-3.14"
      upper="3.14"
      effort="100"
      velocity="100" />
    <mimic
      joint="finger1_outlet_joint"
      multiplier="1"
      offset="0" />
  </joint>
  <link
    name="finger3_base_link">
    <inertial>
      <origin
        xyz="-0.000601794667079381 -0.00110288755052597 0.00521005597269403"
        rpy="0 0 0" />
      <mass
        value="0.00832299911583507" />
      <inertia
        ixx="9.16214830766856E-07"
        ixy="2.57171997871098E-08"
        ixz="1.43130193803543E-08"
        iyy="1.1428046268851E-06"
        iyz="5.78075867067519E-08"
        izz="1.77055158585085E-06" />
    </inertial>
    <visual>
      <origin
        xyz="0 0 0"
        rpy="0 0 0" />
      <geometry>
        <mesh
          filename="package://dcp_description/meshes/gripper/dh3/finger3_base_link.STL" />
      </geometry>
      <material
        name="">
        <color
          rgba="1 1 1 1" />
      </material>
    </visual>
    <collision>
      <origin
        xyz="0 0 0"
        rpy="0 0 0" />
      <geometry>
        <mesh
          filename="package://dcp_description/meshes/gripper/dh3/finger3_base_link.STL" />
      </geometry>
    </collision>
  </link>
  <joint
    name="finger3_base_joint"
    type="revolute">
    <origin
      xyz="-0.016172 -0.028004 0.105"
      rpy="0 0 2.618" />
    <parent
      link="gripper_base_link" />
    <child
      link="finger3_base_link" />
    <axis
      xyz="0 0 -1" />
    <limit
      lower="-3.14"
      upper="3.14"
      effort="100"
      velocity="100" />
    <mimic
      joint="finger1_base_joint"
      multiplier="-1"
      offset="0" />
  </joint>
  <link
    name="finger3_link">
    <inertial>
      <origin
        xyz="0.0210050434938141 0.012249999999974 0.0178290357798672"
        rpy="0 0 0" />
      <mass
        value="0.0055790697798808" />
      <inertia
        ixx="8.99405333082359E-07"
        ixy="9.61461081223117E-19"
        ixz="-5.95537945974827E-07"
        iyy="1.30616755620281E-06"
        iyz="6.24087927058166E-19"
        izz="1.24905466077285E-06" />
    </inertial>
    <visual>
      <origin
        xyz="0 0 0"
        rpy="0 0 0" />
      <geometry>
        <mesh
          filename="package://dcp_description/meshes/gripper/dh3/finger3_link.STL" />
      </geometry>
      <material
        name="">
        <color
          rgba="0.0549019607843137 0.0549019607843137 0.0549019607843137 1" />
      </material>
    </visual>
    <collision>
      <origin
        xyz="0 0 0"
        rpy="0 0 0" />
      <geometry>
        <mesh
          filename="package://dcp_description/meshes/gripper/dh3/finger3_link.STL" />
      </geometry>
    </collision>
  </link>
  <joint
    name="finger3_joint"
    type="revolute">
    <origin
      xyz="0.0122500000000007 -0.00815677008333035 0.0174999999999995"
      rpy="0 0 1.5707963267949" />
    <parent
      link="finger3_base_link" />
    <child
      link="finger3_link" />
    <axis
      xyz="0 -1 0" />
    <limit
      lower="-3.14"
      upper="3.14"
      effort="100"
      velocity="100" />
    <mimic
      joint="finger1_joint"
      multiplier="1"
      offset="0" />
  </joint>
  <link
    name="finger3_tip_link">
    <inertial>
      <origin
        xyz="0.000977114977738613 0.0123819369789457 0.01365909502715"
        rpy="0 0 0" />
      <mass
        value="0.0107564399961694" />
      <inertia
        ixx="1.48949935780095E-06"
        ixy="-7.10872801793197E-09"
        ixz="1.38025629536651E-07"
        iyy="1.35009963358183E-06"
        iyz="1.2426443300764E-08"
        izz="4.77788392346636E-07" />
    </inertial>
    <visual>
      <origin
        xyz="0 0 0"
        rpy="0 0 0" />
      <geometry>
        <mesh
          filename="package://dcp_description/meshes/gripper/dh3/finger3_tip_link.STL" />
      </geometry>
      <material
        name="">
        <color
          rgba="1 1 1 1" />
      </material>
    </visual>
    <collision>
      <origin
        xyz="0 0 0"
        rpy="0 0 0" />
      <geometry>
        <mesh
          filename="package://dcp_description/meshes/gripper/dh3/finger3_tip_link.STL" />
      </geometry>
    </collision>
  </link>
  <joint
    name="finger3_tip_joint"
    type="revolute">
    <origin
      xyz="0.044029 0 0.032962"
      rpy="0 0 0" />
    <parent
      link="finger3_link" />
    <child
      link="finger3_tip_link" />
    <axis
      xyz="0 -1 0" />
    <limit
      lower="-3.14"
      upper="3.14"
      effort="100"
      velocity="100" />
    <mimic
      joint="finger1_joint"
      multiplier="-1"
      offset="0" />
  </joint>
  <link
    name="finger3_outlet_link">
    <inertial>
      <origin
        xyz="0.0205745375238259 -0.00269403304520632 0.0154029215009596"
        rpy="0 0 0" />
      <mass
        value="0.00494212514535466" />
      <inertia
        ixx="3.17522114051902E-07"
        ixy="-1.11543432026918E-10"
        ixz="-3.22041207812167E-07"
        iyy="7.52126509554002E-07"
        iyz="-8.35643256488424E-11"
        izz="5.0659720155034E-07" />
    </inertial>
    <visual>
      <origin
        xyz="0 0 0"
        rpy="0 0 0" />
      <geometry>
        <mesh
          filename="package://dcp_description/meshes/gripper/dh3/finger3_outlet_link.STL" />
      </geometry>
      <material
        name="">
        <color
          rgba="1 1 1 1" />
      </material>
    </visual>
    <collision>
      <origin
        xyz="0 0 0"
        rpy="0 0 0" />
      <geometry>
        <mesh
          filename="package://dcp_description/meshes/gripper/dh3/finger3_outlet_link.STL" />
      </geometry>
    </collision>
  </link>
  <joint
    name="finger3_outlet_joint"
    type="revolute">
    <origin
      xyz="-0.01035 0.0081568 0.0098929"
      rpy="0 0 1.5708" />
    <parent
      link="finger3_base_link" />
    <child
      link="finger3_outlet_link" />
    <axis
      xyz="0 1 0" />
    <limit
      lower="-3.14"
      upper="3.14"
      effort="100"
      velocity="100" />
    <mimic
      joint="finger1_outlet_joint"
      multiplier="1"
      offset="0" />
  </joint>
  <joint name="grasp_joint" type="fixed">
    <origin rpy="0 0 0.0" xyz="0 0 0.2"/>
    <axis xyz="0 0 1"/>
    <parent link="gripper_base_link"/>
    <child link="grasp_frame"/>
  </joint>
  <link name="grasp_frame">
    <inertial>
      <!-- Dummy inertial parameters to avoid link lumping-->
      <mass value="0.01"/>
      <inertia ixx="0.0001" ixy="0.0" ixz="0.0" iyy="0.0001" iyz="0.0" izz="0.0001"/>
      <origin rpy="0 0 0" xyz="0 0 0"/>
    </inertial>
  </link>
</robot>